<?xml version="1.0" ?>
<!-- =================================================================================== -->
<!-- |    This document was autogenerated by xacro from src/dual_piper_description/urdf/dual_piper.urdf.xacro | -->
<!-- |    EDITING THIS FILE BY HAND IS NOT RECOMMENDED                                 | -->
<!-- =================================================================================== -->
<robot name="dual_piper">
  <!-- 1. Add the true root world link (minimal) -->
  <link name="world"/>
  <!-- 2. Rename the existing physical base link -->
  <link name="base">
    <visual>
      <origin rpy="0 0 1.5708" xyz="0 0 0"/>
      <geometry>
        <mesh filename="package://dual_piper_description/meshes/base.STL" scale="0.001 0.001 0.001"/>
      </geometry>
      <material name="gray">
        <color rgba="1 1 0 1"/>
      </material>
    </visual>
    <collision>
      <origin rpy="0 0 1.5708" xyz="0 0 0"/>
      <geometry>
        <mesh filename="package://dual_piper_description/meshes/base.STL" scale="0.001 0.001 0.001"/>
      </geometry>
    </collision>
    <inertial>
      <mass value="1.0"/>
      <origin rpy="0 0 0" xyz="0 0 0"/>
      <inertia ixx="0.1" ixy="0" ixz="0" iyy="0.1" iyz="0" izz="0.1"/>
    </inertial>
  </link>
  <!-- 3. Add a fixed joint connecting world to the base -->
  <joint name="world_to_base" type="fixed">
    <parent link="world"/>
    <child link="base"/>
    <origin rpy="0 0 0" xyz="0 0 0"/>
  </joint>
  <!-- Base link for this arm -->
  <link name="left_base_link">
    <visual>
      <geometry>
        <mesh filename="package://piper_description/meshes/base_link.STL"/>
      </geometry>
      <material name="">
        <color rgba="0.792156862745098 0.819607843137255 0.933333333333333 1"/>
      </material>
    </visual>
    <collision>
      <geometry>
        <mesh filename="package://piper_description/meshes/base_link.STL"/>
      </geometry>
    </collision>
    <inertial>
      <mass value="1.02"/>
      <inertia ixx="0.00267433" ixy="-0.00000073" ixz="-0.00017389" iyy="0.00282612" iyz="0.0000004" izz="0.00089624"/>
    </inertial>
  </link>
  <!-- Mount the arm to the parent -->
  <joint name="left_mount_joint" type="fixed">
    <parent link="base"/>
    <child link="left_base_link"/>
    <origin rpy="0 0 1.5708" xyz="0.19 0 0.515"/>
  </joint>
  <!-- Rest of the arm links -->
  <link name="left_link1">
    <visual>
      <geometry>
        <mesh filename="package://piper_description/meshes/link1.STL"/>
      </geometry>
      <material name="">
        <color rgba="0.792156862745098 0.819607843137255 0.933333333333333 1"/>
      </material>
    </visual>
    <collision>
      <geometry>
        <mesh filename="package://piper_description/meshes/link1.STL"/>
      </geometry>
    </collision>
    <inertial>
      <mass value="0.71"/>
      <inertia ixx="0.00048916" ixy="-0.00000036" ixz="-0.00000224" iyy="0.00040472" iyz="-0.00000242" izz="0.00043982"/>
    </inertial>
  </link>
  <joint name="left_joint1" type="revolute">
    <parent link="left_base_link"/>
    <child link="left_link1"/>
    <origin rpy="0 0 0" xyz="0 0 0.123"/>
    <axis xyz="0 0 1"/>
    <limit effort="100" lower="-2.618" upper="2.168" velocity="5.0"/>
  </joint>
  <link name="left_link2">
    <visual>
      <geometry>
        <mesh filename="package://piper_description/meshes/link2.STL"/>
      </geometry>
      <material name="">
        <color rgba="0.792156862745098 0.819607843137255 0.933333333333333 1"/>
      </material>
    </visual>
    <collision>
      <geometry>
        <mesh filename="package://piper_description/meshes/link2.STL"/>
      </geometry>
    </collision>
    <inertial>
      <mass value="1.17"/>
      <inertia ixx="0.00116918" ixy="-0.00180037" ixz="0.00025146" iyy="0.06785384" iyz="-0.00000455" izz="0.06774489"/>
    </inertial>
  </link>
  <joint name="left_joint2" type="revolute">
    <parent link="left_link1"/>
    <child link="left_link2"/>
    <origin rpy="1.5708 -0.10095 -3.1416" xyz="0 0 0"/>
    <axis xyz="0 0 1"/>
    <limit effort="100" lower="0" upper="3.14" velocity="5.0"/>
  </joint>
  <link name="left_link3">
    <visual>
      <geometry>
        <mesh filename="package://piper_description/meshes/link3.STL"/>
      </geometry>
      <material name="">
        <color rgba="0.792156862745098 0.819607843137255 0.933333333333333 1"/>
      </material>
    </visual>
    <collision>
      <geometry>
        <mesh filename="package://piper_description/meshes/link3.STL"/>
      </geometry>
    </collision>
    <inertial>
      <mass value="0.5"/>
      <inertia ixx="0.01361711" ixy="0.00165794" ixz="-0.00000048" iyy="0.00045024" iyz="-0.00000045" izz="0.01380322"/>
    </inertial>
  </link>
  <joint name="left_joint3" type="revolute">
    <parent link="left_link2"/>
    <child link="left_link3"/>
    <origin rpy="0 0 -1.759" xyz="0.28503 0 0"/>
    <axis xyz="0 0 1"/>
    <limit effort="100" lower="-2.967" upper="0" velocity="5.0"/>
  </joint>
  <!-- Add link4 -->
  <link name="left_link4">
    <inertial>
      <origin rpy="0 0 0" xyz="-9.66635791618542E-05 0.000876064475651083 -0.00496880904640868"/>
      <mass value="0.38"/>
      <inertia ixx="0.00018501" ixy="0.00000054" ixz="0.00000120" iyy="0.00018965" iyz="-0.00000841" izz="0.00015484"/>
    </inertial>
    <visual>
      <geometry>
        <mesh filename="package://piper_description/meshes/link4.STL"/>
      </geometry>
      <material name="">
        <color rgba="0.792156862745098 0.819607843137255 0.933333333333333 1"/>
      </material>
    </visual>
    <collision>
      <geometry>
        <mesh filename="package://piper_description/meshes/link4.STL"/>
      </geometry>
    </collision>
  </link>
  <joint name="left_joint4" type="revolute">
    <parent link="left_link3"/>
    <child link="left_link4"/>
    <origin rpy="1.5708 0 0" xyz="-0.021984 -0.25075 0"/>
    <axis xyz="0 0 1"/>
    <limit effort="100" lower="-1.745" upper="1.745" velocity="5.0"/>
  </joint>
  <!-- Add link5 -->
  <link name="left_link5">
    <inertial>
      <origin rpy="0 0 0" xyz="-4.10554118924211E-05 -0.0566486692356075 -0.0037205791677906"/>
      <mass value="0.383"/>
      <inertia ixx="0.00166169" ixy="0.00000006" ixz="-0.00000007" iyy="0.00018510" iyz="0.00001026" izz="0.00164321"/>
    </inertial>
    <visual>
      <geometry>
        <mesh filename="package://piper_description/meshes/link5.STL"/>
      </geometry>
      <material name="">
        <color rgba="0.792156862745098 0.819607843137255 0.933333333333333 1"/>
      </material>
    </visual>
    <collision>
      <geometry>
        <mesh filename="package://piper_description/meshes/link5.STL"/>
      </geometry>
    </collision>
  </link>
  <joint name="left_joint5" type="revolute">
    <parent link="left_link4"/>
    <child link="left_link5"/>
    <origin rpy="-1.5708 0 0" xyz="0 0 0"/>
    <axis xyz="0 0 1"/>
    <limit effort="100" lower="-1.22" upper="1.22" velocity="5.0"/>
  </joint>
  <!-- Add link6 -->
  <link name="left_link6">
    <inertial>
      <origin rpy="0 0 0" xyz="-8.82590762930069E-05 9.0598378529832E-06 -0.002"/>
      <mass value="0.00699089613564366"/>
      <inertia ixx="5.73015540542155E-07" ixy="-1.98305403089247E-22" ixz="-7.2791893904596E-23" iyy="5.73015540542155E-07" iyz="-3.4146026640245E-24" izz="1.06738869138926E-06"/>
    </inertial>
    <visual>
      <geometry>
        <mesh filename="package://piper_description/meshes/link6.STL"/>
      </geometry>
      <material name="">
        <color rgba="0.898039215686275 0.917647058823529 0.929411764705882 1"/>
      </material>
    </visual>
    <collision>
      <geometry>
        <mesh filename="package://piper_description/meshes/link6.STL"/>
      </geometry>
    </collision>
  </link>
  <joint name="left_joint6" type="revolute">
    <parent link="left_link5"/>
    <child link="left_link6"/>
    <origin rpy="1.5708 0 0" xyz="8.8259E-05 -0.091 0"/>
    <axis xyz="0 0 1"/>
    <limit effort="100" lower="-2.0944" upper="2.0944" velocity="3.0"/>
  </joint>
  <!-- Add gripper base -->
  <link name="left_gripper_base">
    <inertial>
      <origin rpy="0 0 0" xyz="-0.000183807162235591 8.05033155577911E-05 0.0321436689908876"/>
      <mass value="0.45"/>
      <inertia ixx="0.00092934" ixy="0.00000034" ixz="-0.00000738" iyy="0.00071447" iyz="0.00000005" izz="0.00039442"/>
    </inertial>
    <visual>
      <geometry>
        <mesh filename="package://piper_description/meshes/gripper_base.STL"/>
      </geometry>
      <material name="">
        <color rgba="0.792156862745098 0.819607843137255 0.933333333333333 1"/>
      </material>
    </visual>
    <collision>
      <geometry>
        <mesh filename="package://piper_description/meshes/gripper_base.STL"/>
      </geometry>
    </collision>
  </link>
  <joint name="left_joint6_to_gripper_base" type="fixed">
    <parent link="left_link6"/>
    <child link="left_gripper_base"/>
  </joint>
  <!-- Add gripper links -->
  <link name="left_link7">
    <inertial>
      <origin rpy="0 0 0" xyz="0 0 0"/>
      <mass value="0.01"/>
      <inertia ixx="1e-6" ixy="0" ixz="0" iyy="1e-6" iyz="0" izz="1e-6"/>
    </inertial>
    <visual>
      <geometry>
        <mesh filename="package://piper_description/meshes/link7.STL"/>
      </geometry>
      <material name="">
        <color rgba="0.792156862745098 0.819607843137255 0.933333333333333 1"/>
      </material>
    </visual>
    <collision>
      <geometry>
        <mesh filename="package://piper_description/meshes/link7.STL"/>
      </geometry>
    </collision>
  </link>
  <joint name="left_joint7" type="prismatic">
    <parent link="left_gripper_base"/>
    <child link="left_link7"/>
    <origin rpy="1.5708 0 0" xyz="0 0 0.1358"/>
    <axis xyz="0 0 1"/>
    <limit effort="10" lower="0" upper="0.035" velocity="1.0"/>
  </joint>
  <link name="left_link8">
    <inertial>
      <origin rpy="0 0 0" xyz="0 0 0"/>
      <mass value="0.01"/>
      <inertia ixx="1e-6" ixy="0" ixz="0" iyy="1e-6" iyz="0" izz="1e-6"/>
    </inertial>
    <visual>
      <geometry>
        <mesh filename="package://piper_description/meshes/link8.STL"/>
      </geometry>
      <material name="">
        <color rgba="0.792156862745098 0.819607843137255 0.933333333333333 1"/>
      </material>
    </visual>
    <collision>
      <geometry>
        <mesh filename="package://piper_description/meshes/link8.STL"/>
      </geometry>
    </collision>
  </link>
  <joint name="left_joint8" type="prismatic">
    <parent link="left_gripper_base"/>
    <child link="left_link8"/>
    <origin rpy="1.5708 0 -3.1416" xyz="0 0 0.1358"/>
    <axis xyz="0 0 -1"/>
    <limit effort="10" lower="-0.035" upper="0" velocity="1.0"/>
  </joint>
  <!-- Base link for this arm -->
  <link name="right_base_link">
    <visual>
      <geometry>
        <mesh filename="package://piper_description/meshes/base_link.STL"/>
      </geometry>
      <material name="">
        <color rgba="0.792156862745098 0.819607843137255 0.933333333333333 1"/>
      </material>
    </visual>
    <collision>
      <geometry>
        <mesh filename="package://piper_description/meshes/base_link.STL"/>
      </geometry>
    </collision>
    <inertial>
      <mass value="1.02"/>
      <inertia ixx="0.00267433" ixy="-0.00000073" ixz="-0.00017389" iyy="0.00282612" iyz="0.0000004" izz="0.00089624"/>
    </inertial>
  </link>
  <!-- Mount the arm to the parent -->
  <joint name="right_mount_joint" type="fixed">
    <parent link="base"/>
    <child link="right_base_link"/>
    <origin rpy="0 0 1.5708" xyz="-0.21 0 0.515"/>
  </joint>
  <!-- Rest of the arm links -->
  <link name="right_link1">
    <visual>
      <geometry>
        <mesh filename="package://piper_description/meshes/link1.STL"/>
      </geometry>
      <material name="">
        <color rgba="0.792156862745098 0.819607843137255 0.933333333333333 1"/>
      </material>
    </visual>
    <collision>
      <geometry>
        <mesh filename="package://piper_description/meshes/link1.STL"/>
      </geometry>
    </collision>
    <inertial>
      <mass value="0.71"/>
      <inertia ixx="0.00048916" ixy="-0.00000036" ixz="-0.00000224" iyy="0.00040472" iyz="-0.00000242" izz="0.00043982"/>
    </inertial>
  </link>
  <joint name="right_joint1" type="revolute">
    <parent link="right_base_link"/>
    <child link="right_link1"/>
    <origin rpy="0 0 0" xyz="0 0 0.123"/>
    <axis xyz="0 0 1"/>
    <limit effort="100" lower="-2.618" upper="2.168" velocity="5.0"/>
  </joint>
  <link name="right_link2">
    <visual>
      <geometry>
        <mesh filename="package://piper_description/meshes/link2.STL"/>
      </geometry>
      <material name="">
        <color rgba="0.792156862745098 0.819607843137255 0.933333333333333 1"/>
      </material>
    </visual>
    <collision>
      <geometry>
        <mesh filename="package://piper_description/meshes/link2.STL"/>
      </geometry>
    </collision>
    <inertial>
      <mass value="1.17"/>
      <inertia ixx="0.00116918" ixy="-0.00180037" ixz="0.00025146" iyy="0.06785384" iyz="-0.00000455" izz="0.06774489"/>
    </inertial>
  </link>
  <joint name="right_joint2" type="revolute">
    <parent link="right_link1"/>
    <child link="right_link2"/>
    <origin rpy="1.5708 -0.10095 -3.1416" xyz="0 0 0"/>
    <axis xyz="0 0 1"/>
    <limit effort="100" lower="0" upper="3.14" velocity="5.0"/>
  </joint>
  <link name="right_link3">
    <visual>
      <geometry>
        <mesh filename="package://piper_description/meshes/link3.STL"/>
      </geometry>
      <material name="">
        <color rgba="0.792156862745098 0.819607843137255 0.933333333333333 1"/>
      </material>
    </visual>
    <collision>
      <geometry>
        <mesh filename="package://piper_description/meshes/link3.STL"/>
      </geometry>
    </collision>
    <inertial>
      <mass value="0.5"/>
      <inertia ixx="0.01361711" ixy="0.00165794" ixz="-0.00000048" iyy="0.00045024" iyz="-0.00000045" izz="0.01380322"/>
    </inertial>
  </link>
  <joint name="right_joint3" type="revolute">
    <parent link="right_link2"/>
    <child link="right_link3"/>
    <origin rpy="0 0 -1.759" xyz="0.28503 0 0"/>
    <axis xyz="0 0 1"/>
    <limit effort="100" lower="-2.967" upper="0" velocity="5.0"/>
  </joint>
  <!-- Add link4 -->
  <link name="right_link4">
    <inertial>
      <origin rpy="0 0 0" xyz="-9.66635791618542E-05 0.000876064475651083 -0.00496880904640868"/>
      <mass value="0.38"/>
      <inertia ixx="0.00018501" ixy="0.00000054" ixz="0.00000120" iyy="0.00018965" iyz="-0.00000841" izz="0.00015484"/>
    </inertial>
    <visual>
      <geometry>
        <mesh filename="package://piper_description/meshes/link4.STL"/>
      </geometry>
      <material name="">
        <color rgba="0.792156862745098 0.819607843137255 0.933333333333333 1"/>
      </material>
    </visual>
    <collision>
      <geometry>
        <mesh filename="package://piper_description/meshes/link4.STL"/>
      </geometry>
    </collision>
  </link>
  <joint name="right_joint4" type="revolute">
    <parent link="right_link3"/>
    <child link="right_link4"/>
    <origin rpy="1.5708 0 0" xyz="-0.021984 -0.25075 0"/>
    <axis xyz="0 0 1"/>
    <limit effort="100" lower="-1.745" upper="1.745" velocity="5.0"/>
  </joint>
  <!-- Add link5 -->
  <link name="right_link5">
    <inertial>
      <origin rpy="0 0 0" xyz="-4.10554118924211E-05 -0.0566486692356075 -0.0037205791677906"/>
      <mass value="0.383"/>
      <inertia ixx="0.00166169" ixy="0.00000006" ixz="-0.00000007" iyy="0.00018510" iyz="0.00001026" izz="0.00164321"/>
    </inertial>
    <visual>
      <geometry>
        <mesh filename="package://piper_description/meshes/link5.STL"/>
      </geometry>
      <material name="">
        <color rgba="0.792156862745098 0.819607843137255 0.933333333333333 1"/>
      </material>
    </visual>
    <collision>
      <geometry>
        <mesh filename="package://piper_description/meshes/link5.STL"/>
      </geometry>
    </collision>
  </link>
  <joint name="right_joint5" type="revolute">
    <parent link="right_link4"/>
    <child link="right_link5"/>
    <origin rpy="-1.5708 0 0" xyz="0 0 0"/>
    <axis xyz="0 0 1"/>
    <limit effort="100" lower="-1.22" upper="1.22" velocity="5.0"/>
  </joint>
  <!-- Add link6 -->
  <link name="right_link6">
    <inertial>
      <origin rpy="0 0 0" xyz="-8.82590762930069E-05 9.0598378529832E-06 -0.002"/>
      <mass value="0.00699089613564366"/>
      <inertia ixx="5.73015540542155E-07" ixy="-1.98305403089247E-22" ixz="-7.2791893904596E-23" iyy="5.73015540542155E-07" iyz="-3.4146026640245E-24" izz="1.06738869138926E-06"/>
    </inertial>
    <visual>
      <geometry>
        <mesh filename="package://piper_description/meshes/link6.STL"/>
      </geometry>
      <material name="">
        <color rgba="0.898039215686275 0.917647058823529 0.929411764705882 1"/>
      </material>
    </visual>
    <collision>
      <geometry>
        <mesh filename="package://piper_description/meshes/link6.STL"/>
      </geometry>
    </collision>
  </link>
  <joint name="right_joint6" type="revolute">
    <parent link="right_link5"/>
    <child link="right_link6"/>
    <origin rpy="1.5708 0 0" xyz="8.8259E-05 -0.091 0"/>
    <axis xyz="0 0 1"/>
    <limit effort="100" lower="-2.0944" upper="2.0944" velocity="3.0"/>
  </joint>
  <!-- Add gripper base -->
  <link name="right_gripper_base">
    <inertial>
      <origin rpy="0 0 0" xyz="-0.000183807162235591 8.05033155577911E-05 0.0321436689908876"/>
      <mass value="0.45"/>
      <inertia ixx="0.00092934" ixy="0.00000034" ixz="-0.00000738" iyy="0.00071447" iyz="0.00000005" izz="0.00039442"/>
    </inertial>
    <visual>
      <geometry>
        <mesh filename="package://piper_description/meshes/gripper_base.STL"/>
      </geometry>
      <material name="">
        <color rgba="0.792156862745098 0.819607843137255 0.933333333333333 1"/>
      </material>
    </visual>
    <collision>
      <geometry>
        <mesh filename="package://piper_description/meshes/gripper_base.STL"/>
      </geometry>
    </collision>
  </link>
  <joint name="right_joint6_to_gripper_base" type="fixed">
    <parent link="right_link6"/>
    <child link="right_gripper_base"/>
  </joint>
  <!-- Add gripper links -->
  <link name="right_link7">
    <inertial>
      <origin rpy="0 0 0" xyz="0 0 0"/>
      <mass value="0.01"/>
      <inertia ixx="1e-6" ixy="0" ixz="0" iyy="1e-6" iyz="0" izz="1e-6"/>
    </inertial>
    <visual>
      <geometry>
        <mesh filename="package://piper_description/meshes/link7.STL"/>
      </geometry>
      <material name="">
        <color rgba="0.792156862745098 0.819607843137255 0.933333333333333 1"/>
      </material>
    </visual>
    <collision>
      <geometry>
        <mesh filename="package://piper_description/meshes/link7.STL"/>
      </geometry>
    </collision>
  </link>
  <joint name="right_joint7" type="prismatic">
    <parent link="right_gripper_base"/>
    <child link="right_link7"/>
    <origin rpy="1.5708 0 0" xyz="0 0 0.1358"/>
    <axis xyz="0 0 1"/>
    <limit effort="10" lower="0" upper="0.035" velocity="1.0"/>
  </joint>
  <link name="right_link8">
    <inertial>
      <origin rpy="0 0 0" xyz="0 0 0"/>
      <mass value="0.01"/>
      <inertia ixx="1e-6" ixy="0" ixz="0" iyy="1e-6" iyz="0" izz="1e-6"/>
    </inertial>
    <visual>
      <geometry>
        <mesh filename="package://piper_description/meshes/link8.STL"/>
      </geometry>
      <material name="">
        <color rgba="0.792156862745098 0.819607843137255 0.933333333333333 1"/>
      </material>
    </visual>
    <collision>
      <geometry>
        <mesh filename="package://piper_description/meshes/link8.STL"/>
      </geometry>
    </collision>
  </link>
  <joint name="right_joint8" type="prismatic">
    <parent link="right_gripper_base"/>
    <child link="right_link8"/>
    <origin rpy="1.5708 0 -3.1416" xyz="0 0 0.1358"/>
    <axis xyz="0 0 -1"/>
    <limit effort="10" lower="-0.035" upper="0" velocity="1.0"/>
  </joint>
</robot>
