<?xml version="1.0"?>
<robot xmlns:xacro="http://www.ros.org/wiki/xacro" name="dual_piper">

    <!-- 1. Add the true root world link (minimal) -->
    <link name="world"/>

    <!-- 2. Rename the existing physical base link -->
    <link name="base">
        <visual>
            <origin xyz="0 0 0" rpy="0 0 1.5708"/>
            <geometry>
                <mesh filename="package://dual_piper_description/meshes/base.STL" scale="0.001 0.001 0.001"/>
            </geometry>
            <material name="gray">
                <color rgba="1 1 0 1"/>
            </material>
        </visual>
        <collision>
            <origin xyz="0 0 0" rpy="0 0 1.5708"/>
            <geometry>
                <mesh filename="package://dual_piper_description/meshes/base.STL" scale="0.001 0.001 0.001"/>
            </geometry>
        </collision>
        <inertial>
            <mass value="1.0"/>
            <origin xyz="0 0 0" rpy="0 0 0"/>
            <inertia ixx="0.1" ixy="0" ixz="0" iyy="0.1" iyz="0" izz="0.1"/>
        </inertial>
    </link>

    <!-- 3. Add a fixed joint connecting world to the base -->
    <joint name="world_to_base" type="fixed">
        <parent link="world"/>
        <child link="base"/>
        <origin xyz="0 0 0" rpy="0 0 0"/>
    </joint>

    <!-- Create a macro for the Piper arm -->
    <xacro:macro name="piper_arm" params="prefix parent_link x y z roll pitch yaw">
        <!-- Base link for this arm -->
        <link name="${prefix}base_link">
            <visual>
                <geometry>
                    <mesh filename="package://piper_description/meshes/base_link.STL"/>
                </geometry>
                <material name="">
                    <color rgba="0.792156862745098 0.819607843137255 0.933333333333333 1"/>
                </material>
            </visual>
            <collision>
                <geometry>
                    <mesh filename="package://piper_description/meshes/base_link.STL"/>
                </geometry>
            </collision>
            <inertial>
                <mass value="1.02"/>
                <inertia ixx="0.00267433" ixy="-0.00000073" ixz="-0.00017389" iyy="0.00282612" iyz="0.0000004" izz="0.00089624"/>
            </inertial>
        </link>

        <!-- Mount the arm to the parent -->
        <joint name="${prefix}mount_joint" type="fixed">
            <parent link="${parent_link}"/>
            <child link="${prefix}base_link"/>
            <origin xyz="${x} ${y} ${z}" rpy="${roll} ${pitch} ${yaw}"/>
        </joint>

        <!-- Rest of the arm links -->
        <link name="${prefix}link1">
            <visual>
                <geometry>
                    <mesh filename="package://piper_description/meshes/link1.STL"/>
                </geometry>
                <material name="">
                    <color rgba="0.792156862745098 0.819607843137255 0.933333333333333 1"/>
                </material>
            </visual>
            <collision>
                <geometry>
                    <mesh filename="package://piper_description/meshes/link1.STL"/>
                </geometry>
            </collision>
            <inertial>
                <mass value="0.71"/>
                <inertia ixx="0.00048916" ixy="-0.00000036" ixz="-0.00000224" iyy="0.00040472" iyz="-0.00000242" izz="0.00043982"/>
            </inertial>
        </link>

        <joint name="${prefix}joint1" type="revolute">
            <parent link="${prefix}base_link"/>
            <child link="${prefix}link1"/>
            <origin xyz="0 0 0.123" rpy="0 0 0"/>
            <axis xyz="0 0 1"/>
            <limit lower="-2.618" upper="2.168" effort="100" velocity="5.0"/>
        </joint>

        <link name="${prefix}link2">
            <visual>
                <geometry>
                    <mesh filename="package://piper_description/meshes/link2.STL"/>
                </geometry>
                <material name="">
                    <color rgba="0.792156862745098 0.819607843137255 0.933333333333333 1"/>
                </material>
            </visual>
            <collision>
                <geometry>
                    <mesh filename="package://piper_description/meshes/link2.STL"/>
                </geometry>
            </collision>
            <inertial>
                <mass value="1.17"/>
                <inertia ixx="0.00116918" ixy="-0.00180037" ixz="0.00025146" iyy="0.06785384" iyz="-0.00000455" izz="0.06774489"/>
            </inertial>
        </link>

        <joint name="${prefix}joint2" type="revolute">
            <parent link="${prefix}link1"/>
            <child link="${prefix}link2"/>
            <origin xyz="0 0 0" rpy="1.5708 -0.10095 -3.1416"/>
            <axis xyz="0 0 1"/>
            <limit lower="0" upper="3.14" effort="100" velocity="5.0"/>
        </joint>

        <link name="${prefix}link3">
            <visual>
                <geometry>
                    <mesh filename="package://piper_description/meshes/link3.STL"/>
                </geometry>
                <material name="">
                    <color rgba="0.792156862745098 0.819607843137255 0.933333333333333 1"/>
                </material>
            </visual>
            <collision>
                <geometry>
                    <mesh filename="package://piper_description/meshes/link3.STL"/>
                </geometry>
            </collision>
            <inertial>
                <mass value="0.5"/>
                <inertia ixx="0.01361711" ixy="0.00165794" ixz="-0.00000048" iyy="0.00045024" iyz="-0.00000045" izz="0.01380322"/>
            </inertial>
        </link>

        <joint name="${prefix}joint3" type="revolute">
            <parent link="${prefix}link2"/>
            <child link="${prefix}link3"/>
            <origin xyz="0.28503 0 0" rpy="0 0 -1.759"/>
            <axis xyz="0 0 1"/>
            <limit lower="-2.967" upper="0" effort="100" velocity="5.0"/>
        </joint>

        <!-- Add link4 -->
        <link name="${prefix}link4">
            <inertial>
                <origin xyz="-9.66635791618542E-05 0.000876064475651083 -0.00496880904640868" rpy="0 0 0"/>
                <mass value="0.38"/>
                <inertia ixx="0.00018501" ixy="0.00000054" ixz="0.00000120" iyy="0.00018965" iyz="-0.00000841" izz="0.00015484"/>
            </inertial>
            <visual>
                <geometry>
                    <mesh filename="package://piper_description/meshes/link4.STL"/>
                </geometry>
                <material name="">
                    <color rgba="0.792156862745098 0.819607843137255 0.933333333333333 1"/>
                </material>
            </visual>
            <collision>
                <geometry>
                    <mesh filename="package://piper_description/meshes/link4.STL"/>
                </geometry>
            </collision>
        </link>

        <joint name="${prefix}joint4" type="revolute">
            <parent link="${prefix}link3"/>
            <child link="${prefix}link4"/>
            <origin xyz="-0.021984 -0.25075 0" rpy="1.5708 0 0"/>
            <axis xyz="0 0 1"/>
            <limit lower="-1.745" upper="1.745" effort="100" velocity="5.0"/>
        </joint>

        <!-- Add link5 -->
        <link name="${prefix}link5">
            <inertial>
                <origin xyz="-4.10554118924211E-05 -0.0566486692356075 -0.0037205791677906" rpy="0 0 0"/>
                <mass value="0.383"/>
                <inertia ixx="0.00166169" ixy="0.00000006" ixz="-0.00000007" iyy="0.00018510" iyz="0.00001026" izz="0.00164321"/>
            </inertial>
            <visual>
                <geometry>
                    <mesh filename="package://piper_description/meshes/link5.STL"/>
                </geometry>
                <material name="">
                    <color rgba="0.792156862745098 0.819607843137255 0.933333333333333 1"/>
                </material>
            </visual>
            <collision>
                <geometry>
                    <mesh filename="package://piper_description/meshes/link5.STL"/>
                </geometry>
            </collision>
        </link>

        <joint name="${prefix}joint5" type="revolute">
            <parent link="${prefix}link4"/>
            <child link="${prefix}link5"/>
            <origin xyz="0 0 0" rpy="-1.5708 0 0"/>
            <axis xyz="0 0 1"/>
            <limit lower="-1.22" upper="1.22" effort="100" velocity="5.0"/>
        </joint>

        <!-- Add link6 -->
        <link name="${prefix}link6">
            <inertial>
                <origin xyz="-8.82590762930069E-05 9.0598378529832E-06 -0.002" rpy="0 0 0"/>
                <mass value="0.00699089613564366"/>
                <inertia ixx="5.73015540542155E-07" ixy="-1.98305403089247E-22" ixz="-7.2791893904596E-23" iyy="5.73015540542155E-07" iyz="-3.4146026640245E-24" izz="1.06738869138926E-06"/>
            </inertial>
            <visual>
                <geometry>
                    <mesh filename="package://piper_description/meshes/link6.STL"/>
                </geometry>
                <material name="">
                    <color rgba="0.898039215686275 0.917647058823529 0.929411764705882 1"/>
                </material>
            </visual>
            <collision>
                <geometry>
                    <mesh filename="package://piper_description/meshes/link6.STL"/>
                </geometry>
            </collision>
        </link>

        <joint name="${prefix}joint6" type="revolute">
            <parent link="${prefix}link5"/>
            <child link="${prefix}link6"/>
            <origin xyz="8.8259E-05 -0.091 0" rpy="1.5708 0 0"/>
            <axis xyz="0 0 1"/>
            <limit lower="-2.0944" upper="2.0944" effort="100" velocity="3.0"/>
        </joint>

        <!-- Add gripper base -->
        <link name="${prefix}gripper_base">
            <inertial>
                <origin xyz="-0.000183807162235591 8.05033155577911E-05 0.0321436689908876" rpy="0 0 0"/>
                <mass value="0.45"/>
                <inertia ixx="0.00092934" ixy="0.00000034" ixz="-0.00000738" iyy="0.00071447" iyz="0.00000005" izz="0.00039442"/>
            </inertial>
            <visual>
                <geometry>
                    <mesh filename="package://piper_description/meshes/gripper_base.STL"/>
                </geometry>
                <material name="">
                    <color rgba="0.792156862745098 0.819607843137255 0.933333333333333 1"/>
                </material>
            </visual>
            <collision>
                <geometry>
                    <mesh filename="package://piper_description/meshes/gripper_base.STL"/>
                </geometry>
            </collision>
        </link>

        <joint name="${prefix}joint6_to_gripper_base" type="fixed">
            <parent link="${prefix}link6"/>
            <child link="${prefix}gripper_base"/>
        </joint>

        <!-- Add gripper links -->
        <link name="${prefix}link7">
            <inertial>
                <origin xyz="0 0 0" rpy="0 0 0"/>
                <mass value="0.01"/>
                <inertia ixx="1e-6" ixy="0" ixz="0" iyy="1e-6" iyz="0" izz="1e-6"/>
            </inertial>
            <visual>
                <geometry>
                    <mesh filename="package://piper_description/meshes/link7.STL"/>
                </geometry>
                <material name="">
                    <color rgba="0.792156862745098 0.819607843137255 0.933333333333333 1"/>
                </material>
            </visual>
            <collision>
                <geometry>
                    <mesh filename="package://piper_description/meshes/link7.STL"/>
                </geometry>
            </collision>
        </link>

        <joint name="${prefix}joint7" type="prismatic">
            <parent link="${prefix}gripper_base"/>
            <child link="${prefix}link7"/>
            <origin xyz="0 0 0.1358" rpy="1.5708 0 0"/>
            <axis xyz="0 0 1"/>
            <limit lower="0" upper="0.035" effort="10" velocity="1.0"/>
        </joint>

        <link name="${prefix}link8">
            <inertial>
                <origin xyz="0 0 0" rpy="0 0 0"/>
                <mass value="0.01"/>
                <inertia ixx="1e-6" ixy="0" ixz="0" iyy="1e-6" iyz="0" izz="1e-6"/>
            </inertial>
            <visual>
                <geometry>
                    <mesh filename="package://piper_description/meshes/link8.STL"/>
                </geometry>
                <material name="">
                    <color rgba="0.792156862745098 0.819607843137255 0.933333333333333 1"/>
                </material>
            </visual>
            <collision>
                <geometry>
                    <mesh filename="package://piper_description/meshes/link8.STL"/>
                </geometry>
            </collision>
        </link>

        <joint name="${prefix}joint8" type="prismatic">
            <parent link="${prefix}gripper_base"/>
            <child link="${prefix}link8"/>
            <origin xyz="0 0 0.1358" rpy="1.5708 0 -3.1416"/>
            <axis xyz="0 0 -1"/>
            <limit lower="-0.035" upper="0" effort="10" velocity="1.0"/>
        </joint>
    </xacro:macro>

    <!-- 4. Update parent_link to be the renamed 'base' link -->
    <!-- Create the left arm -->
    <xacro:piper_arm prefix="left_" parent_link="base" x="0.19" y="0" z="0.515" roll="0" pitch="0" yaw="1.5708"/>

    <!-- Create the right arm -->
    <xacro:piper_arm prefix="right_" parent_link="base" x="-0.21" y="0" z="0.515" roll="0" pitch="0" yaw="1.5708"/>

</robot> 